<mujoco model="ergoCub">
  <compiler angle="radian"/>
  <statistic meansize="0.0919128" extent="1.66842" center="0.0164501 0.000867736 -0.0627866"/>
  <asset>
    <mesh name="sim_ecub_root_link_prt" file="sim_ecub_root_link_prt.stl" scale="0.001 0.001 0.001"/>
    <mesh name="sim_ecub_r_hip_1_prt" file="sim_ecub_r_hip_1_prt.stl" scale="0.001 0.001 0.001"/>
    <mesh name="sim_ecub_r_hip_2_prt" file="sim_ecub_r_hip_2_prt.stl" scale="0.001 0.001 0.001"/>
    <mesh name="sim_ecub_r_hip_3_prt" file="sim_ecub_r_hip_3_prt.stl" scale="0.001 0.001 0.001"/>
    <mesh name="sim_ecub_r_upper_leg_prt" file="sim_ecub_r_upper_leg_prt.stl" scale="0.001 0.001 0.001"/>
    <mesh name="sim_ecub_r_lower_leg_prt" file="sim_ecub_r_lower_leg_prt.stl" scale="0.001 0.001 0.001"/>
    <mesh name="sim_ecub_r_ankle_1_prt" file="sim_ecub_r_ankle_1_prt.stl" scale="0.001 0.001 0.001"/>
    <mesh name="sim_ecub_r_ankle_2_prt" file="sim_ecub_r_ankle_2_prt.stl" scale="0.001 0.001 0.001"/>
    <mesh name="sim_ecub_r_foot_rear_prt" file="sim_ecub_r_foot_rear_prt.stl" scale="0.001 0.001 0.001"/>
    <mesh name="sim_ecub_r_foot_front_prt" file="sim_ecub_r_foot_front_prt.stl" scale="0.001 0.001 0.001"/>
    <mesh name="sim_ecub_l_hip_1_prt" file="sim_ecub_l_hip_1_prt.stl" scale="0.001 0.001 0.001"/>
    <mesh name="sim_ecub_l_hip_2_prt" file="sim_ecub_l_hip_2_prt.stl" scale="0.001 0.001 0.001"/>
    <mesh name="sim_ecub_l_hip_3_prt" file="sim_ecub_l_hip_3_prt.stl" scale="0.001 0.001 0.001"/>
    <mesh name="sim_ecub_l_upper_leg_prt" file="sim_ecub_l_upper_leg_prt.stl" scale="0.001 0.001 0.001"/>
    <mesh name="sim_ecub_l_lower_leg_prt" file="sim_ecub_l_lower_leg_prt.stl" scale="0.001 0.001 0.001"/>
    <mesh name="sim_ecub_l_ankle_1_prt" file="sim_ecub_l_ankle_1_prt.stl" scale="0.001 0.001 0.001"/>
    <mesh name="sim_ecub_l_ankle_2_prt" file="sim_ecub_l_ankle_2_prt.stl" scale="0.001 0.001 0.001"/>
    <mesh name="sim_ecub_l_foot_front_prt" file="sim_ecub_l_foot_front_prt.stl" scale="0.001 0.001 0.001"/>
    <mesh name="sim_ecub_l_foot_rear_prt" file="sim_ecub_l_foot_rear_prt.stl" scale="0.001 0.001 0.001"/>
    <mesh name="sim_ecub_torso_1_prt" file="sim_ecub_torso_1_prt.stl" scale="0.001 0.001 0.001"/>
    <mesh name="sim_ecub_torso_2_prt" file="sim_ecub_torso_2_prt.stl" scale="0.001 0.001 0.001"/>
    <mesh name="sim_ecub_chest_prt" file="sim_ecub_chest_prt.stl" scale="0.001 0.001 0.001"/>
    <mesh name="sim_ecub_head_neck_2_prt" file="sim_ecub_head_neck_2_prt.stl" scale="0.001 0.001 0.001"/>
    <mesh name="sim_ecub_head_neck_3_prt" file="sim_ecub_head_neck_3_prt.stl" scale="0.001 0.001 0.001"/>
    <mesh name="sim_ecub_head_prt" file="sim_ecub_head_prt.stl" scale="0.001 0.001 0.001"/>
    <mesh name="sim_ecub_realsense_prt" file="sim_ecub_realsense_prt.stl" scale="0.001 0.001 0.001"/>
    <mesh name="sim_ecub_r_shoulder_1_prt" file="sim_ecub_r_shoulder_1_prt.stl" scale="0.001 0.001 0.001"/>
    <mesh name="sim_ecub_r_shoulder_2_prt" file="sim_ecub_r_shoulder_2_prt.stl" scale="0.001 0.001 0.001"/>
    <mesh name="sim_ecub_r_shoulder_3_prt" file="sim_ecub_r_shoulder_3_prt.stl" scale="0.001 0.001 0.001"/>
    <mesh name="sim_ecub_r_upperarm_prt" file="sim_ecub_r_upperarm_prt.stl" scale="0.001 0.001 0.001"/>
    <mesh name="sim_ecub_r_forearm_prt" file="sim_ecub_r_forearm_prt.stl" scale="0.001 0.001 0.001"/>
    <mesh name="sim_ecub_r_wrist_1_prt" file="sim_ecub_r_wrist_1_prt.stl" scale="0.001 0.001 0.001"/>
    <mesh name="sim_ecub_r_wrist_2_prt" file="sim_ecub_r_wrist_2_prt.stl" scale="0.001 0.001 0.001"/>
    <mesh name="sim_ecub_r_hand_palm_prt" file="sim_ecub_r_hand_palm_prt.stl" scale="0.001 0.001 0.001"/>
    <mesh name="sim_ecub_r_hand_pinkie_1_prt" file="sim_ecub_r_hand_pinkie_1_prt.stl" scale="0.001 0.001 0.001"/>
    <mesh name="sim_ecub_r_hand_pinkie_2_prt" file="sim_ecub_r_hand_pinkie_2_prt.stl" scale="0.001 0.001 0.001"/>
    <mesh name="sim_ecub_r_hand_thumb_1_prt" file="sim_ecub_r_hand_thumb_1_prt.stl" scale="0.001 0.001 0.001"/>
    <mesh name="sim_ecub_r_hand_thumb_2_prt" file="sim_ecub_r_hand_thumb_2_prt.stl" scale="0.001 0.001 0.001"/>
    <mesh name="sim_ecub_r_hand_thumb_3_prt" file="sim_ecub_r_hand_thumb_3_prt.stl" scale="0.001 0.001 0.001"/>
    <mesh name="sim_ecub_r_hand_middle_1_prt" file="sim_ecub_r_hand_middle_1_prt.stl" scale="0.001 0.001 0.001"/>
    <mesh name="sim_ecub_r_hand_middle_2_prt" file="sim_ecub_r_hand_middle_2_prt.stl" scale="0.001 0.001 0.001"/>
    <mesh name="sim_ecub_r_hand_ring_1_prt" file="sim_ecub_r_hand_ring_1_prt.stl" scale="0.001 0.001 0.001"/>
    <mesh name="sim_ecub_r_hand_ring_2_prt" file="sim_ecub_r_hand_ring_2_prt.stl" scale="0.001 0.001 0.001"/>
    <mesh name="sim_ecub_r_hand_index_1_prt" file="sim_ecub_r_hand_index_1_prt.stl" scale="0.001 0.001 0.001"/>
    <mesh name="sim_ecub_r_hand_index_2_prt" file="sim_ecub_r_hand_index_2_prt.stl" scale="0.001 0.001 0.001"/>
    <mesh name="sim_ecub_r_hand_index_3_prt" file="sim_ecub_r_hand_index_3_prt.stl" scale="0.001 0.001 0.001"/>
    <mesh name="sim_ecub_l_shoulder_1_prt" file="sim_ecub_l_shoulder_1_prt.stl" scale="0.001 0.001 0.001"/>
    <mesh name="sim_ecub_l_shoulder_2_prt" file="sim_ecub_l_shoulder_2_prt.stl" scale="0.001 0.001 0.001"/>
    <mesh name="sim_ecub_l_shoulder_3_prt" file="sim_ecub_l_shoulder_3_prt.stl" scale="0.001 0.001 0.001"/>
    <mesh name="sim_ecub_l_upperarm_prt" file="sim_ecub_l_upperarm_prt.stl" scale="0.001 0.001 0.001"/>
    <mesh name="sim_ecub_l_forearm_prt" file="sim_ecub_l_forearm_prt.stl" scale="0.001 0.001 0.001"/>
    <mesh name="sim_ecub_l_wrist_1_prt" file="sim_ecub_l_wrist_1_prt.stl" scale="0.001 0.001 0.001"/>
    <mesh name="sim_ecub_l_wrist_2_prt" file="sim_ecub_l_wrist_2_prt.stl" scale="0.001 0.001 0.001"/>
    <mesh name="sim_ecub_l_hand_palm_prt" file="sim_ecub_l_hand_palm_prt.stl" scale="0.001 0.001 0.001"/>
    <mesh name="sim_ecub_l_hand_ring_1_prt" file="sim_ecub_l_hand_ring_1_prt.stl" scale="0.001 0.001 0.001"/>
    <mesh name="sim_ecub_l_hand_ring_2_prt" file="sim_ecub_l_hand_ring_2_prt.stl" scale="0.001 0.001 0.001"/>
    <mesh name="sim_ecub_l_hand_index_1_prt" file="sim_ecub_l_hand_index_1_prt.stl" scale="0.001 0.001 0.001"/>
    <mesh name="sim_ecub_l_hand_index_2_prt" file="sim_ecub_l_hand_index_2_prt.stl" scale="0.001 0.001 0.001"/>
    <mesh name="sim_ecub_l_hand_index_3_prt" file="sim_ecub_l_hand_index_3_prt.stl" scale="0.001 0.001 0.001"/>
    <mesh name="sim_ecub_l_hand_middle_1_prt" file="sim_ecub_l_hand_middle_1_prt.stl" scale="0.001 0.001 0.001"/>
    <mesh name="sim_ecub_l_hand_middle_2_prt" file="sim_ecub_l_hand_middle_2_prt.stl" scale="0.001 0.001 0.001"/>
    <mesh name="sim_ecub_l_hand_thumb_1_prt" file="sim_ecub_l_hand_thumb_1_prt.stl" scale="0.001 0.001 0.001"/>
    <mesh name="sim_ecub_l_hand_thumb_2_prt" file="sim_ecub_l_hand_thumb_2_prt.stl" scale="0.001 0.001 0.001"/>
    <mesh name="sim_ecub_l_hand_thumb_3_prt" file="sim_ecub_l_hand_thumb_3_prt.stl" scale="0.001 0.001 0.001"/>
    <mesh name="sim_ecub_l_hand_pinkie_1_prt" file="sim_ecub_l_hand_pinkie_1_prt.stl" scale="0.001 0.001 0.001"/>
    <mesh name="sim_ecub_l_hand_pinkie_2_prt" file="sim_ecub_l_hand_pinkie_2_prt.stl" scale="0.001 0.001 0.001"/>
  </asset>
  <worldbody>
    <geom pos="0 0 0.1785" quat="0.707107 0 0 0.707107" type="mesh" rgba="0.7 0.7 0.7 1" mesh="sim_ecub_root_link_prt"/>
    <body name="r_hip_1" pos="0.0211 -0.0505 0">
      <inertial pos="-0.0040321 -0.0282494 -0.000674" quat="0.471583 0.463949 0.507259 0.552313" mass="2.23209" diaginertia="0.00270348 0.00246138 0.00220385"/>
      <joint name="r_hip_pitch" pos="0 0 0" axis="0 -1 0" range="-0.750492 1.79769" damping="2"/>
      <geom pos="-0.0211 0.0505 0.1785" quat="0.707107 0 0 0.707107" type="mesh" rgba="0.7 0.7 0.7 1" mesh="sim_ecub_r_hip_1_prt"/>
      <body name="r_hip_2" pos="-0.04725 -0.0331 -0.009">
        <inertial pos="0.0206737 0.00690112 -0.0935168" quat="0.685131 -0.126138 -0.177679 0.695065" mass="3.9815" diaginertia="0.02644 0.0237871 0.00862537"/>
        <joint name="r_hip_roll" pos="0 0 0" axis="-1 0 0" range="-0.279253 1.90241" damping="2"/>
        <geom pos="0.0262 0.0836 0.1875" quat="0.707107 0 0 0.707107" type="mesh" rgba="0.7 0.7 0.7 1" mesh="sim_ecub_r_hip_2_prt"/>
        <geom pos="0.0262 0.0836 0.1875" quat="0.707107 0 0 0.707107" type="mesh" rgba="0.3 0.3 0.3 1" mesh="sim_ecub_r_hip_3_prt"/>
        <body name="r_upper_leg" pos="0.0367 0.015 -0.1624" quat="1 0 0 5.9369e-07">
          <inertial pos="0.00851748 -0.0144685 -0.12675" quat="0.752216 -0.0338778 -0.00759657 0.658001" mass="2.78492" diaginertia="0.0121302 0.0118863 0.00221412"/>
          <joint name="r_hip_yaw" pos="0 0 0" axis="0 0 -1" range="-1.37881 1.37881" damping="2"/>
          <geom pos="-0.0105 0.0686 0.3499" quat="0.707107 0 0 0.707107" type="mesh" rgba="0.7 0.7 0.7 1" mesh="sim_ecub_r_upper_leg_prt"/>
          <body name="r_lower_leg" pos="0.0106 0.00789999 -0.1797" quat="0 1 -5.9369e-07 0">
            <inertial pos="0.0011585 0.0062002 0.214259" quat="0.00842304 0.725858 -0.687437 0.0221305" mass="3.74161" diaginertia="0.0473358 0.0460276 0.00468999"/>
            <joint name="r_knee" pos="0 0 0" axis="0 1 0" range="-1.81514 0.10472" damping="2"/>
            <geom pos="-0.0211 -0.0607 -0.5296" quat="0 0.707107 -0.707107 0" type="mesh" rgba="0.3 0.3 0.3 1" mesh="sim_ecub_r_lower_leg_prt"/>
            <body name="r_ankle_1" pos="0 0.0319 0.321" quat="0 1 0 0">
              <inertial pos="-0.0013672 -0.0006602 -0.014087" quat="0.416612 0.576846 0.372407 0.595816" mass="0.348128" diaginertia="0.000597996 0.000440984 0.000246481"/>
              <joint name="r_ankle_pitch" pos="0 0 0" axis="0 1 0" range="-0.785398 0.785398" damping="2"/>
              <geom pos="-0.0211 0.0926 0.8506" quat="0.707107 0 0 0.707107" type="mesh" rgba="0.7 0.7 0.7 1" mesh="sim_ecub_r_ankle_1_prt"/>
              <body name="r_ankle_2" pos="-0.05275 0.0182 -0.035">
                <inertial pos="0.0484804 -6.71428e-05 -0.0336846" quat="0.464503 0.527312 0.567412 0.429211" mass="1.98403" diaginertia="0.0126381 0.0123127 0.00281191"/>
                <joint name="r_ankle_roll" pos="0 0 0" axis="-1 0 0" range="-0.436332 0.436332" damping="2"/>
                <geom pos="0.03165 0.0744 0.8856" quat="0.707107 0 0 0.707107" type="mesh" rgba="0.3 0.3 0.3 1" mesh="sim_ecub_r_ankle_2_prt"/>
                <geom pos="0.0316 0.0744 0.8856" quat="0.707107 0 0 0.707107" type="mesh" rgba="1 0.51 0 1" mesh="sim_ecub_r_foot_rear_prt"/>
                <geom pos="0.03165 0.0744 0.8856" quat="0.707107 0 0 0.707107" type="mesh" rgba="1 0.51 0 1" mesh="sim_ecub_r_foot_front_prt"/>
              </body>
            </body>
          </body>
        </body>
      </body>
    </body>
    <body name="l_hip_1" pos="0.0211 0.0505 0">
      <inertial pos="-0.0040154 0.0282473 -0.000681" quat="0.551419 0.506606 0.463763 0.473509" mass="2.23177" diaginertia="0.00270283 0.00246163 0.00220285"/>
      <joint name="l_hip_pitch" pos="0 0 0" axis="0 -1 0" range="-0.750492 1.79769" damping="2"/>
      <geom pos="-0.0211 -0.0505 0.1785" quat="0.707107 0 0 0.707107" type="mesh" rgba="0.7 0.7 0.7 1" mesh="sim_ecub_l_hip_1_prt"/>
      <body name="l_hip_2" pos="-0.04725 0.0331 -0.009">
        <inertial pos="0.0206874 -0.00690172 -0.0935735" quat="0.69574 -0.176627 -0.125492 0.684836" mass="3.98136" diaginertia="0.0265634 0.0238959 0.00864075"/>
        <joint name="l_hip_roll" pos="0 0 0" axis="1 0 0" range="-0.279253 1.90241" damping="2"/>
        <geom pos="0.02615 -0.0836 0.1875" quat="0.707107 0 0 0.707107" type="mesh" rgba="0.7 0.7 0.7 1" mesh="sim_ecub_l_hip_2_prt"/>
        <geom pos="0.02615 -0.0836 0.1875" quat="0.707107 0 0 0.707107" type="mesh" rgba="0.3 0.3 0.3 1" mesh="sim_ecub_l_hip_3_prt"/>
        <body name="l_upper_leg" pos="0.0367 -0.015 -0.1624">
          <inertial pos="0.0085035 0.0144849 -0.126747" quat="0.666541 -0.00759957 -0.0335156 0.744676" mass="2.78492" diaginertia="0.0121286 0.0118796 0.00220771"/>
          <joint name="l_hip_yaw" pos="0 0 0" axis="0 0 1" range="-1.37881 1.37881" damping="2"/>
          <geom pos="-0.01055 -0.0686 0.3499" quat="0.707107 0 0 0.707107" type="mesh" rgba="0.7 0.7 0.7 1" mesh="sim_ecub_l_upper_leg_prt"/>
          <body name="l_lower_leg" pos="0.0106 -0.0079 -0.1797" quat="0 1 0 0">
            <inertial pos="0.0013845 -0.0061871 0.21426" quat="-0.0218229 0.692096 -0.721423 -0.00870268" mass="3.74161" diaginertia="0.0473316 0.0460262 0.00468891"/>
            <joint name="l_knee" pos="0 0 0" axis="0 1 0" range="-1.81514 0.10472" damping="2"/>
            <geom pos="-0.02115 0.0607 -0.5296" quat="0 0.707107 -0.707107 0" type="mesh" rgba="0.3 0.3 0.3 1" mesh="sim_ecub_l_lower_leg_prt"/>
            <body name="l_ankle_1" pos="0 -0.0319 0.321" quat="0 1 0 0">
              <inertial pos="-0.0013852 0.0006602 -0.014087" quat="0.592894 0.375471 0.580004 0.413634" mass="0.348128" diaginertia="0.000597982 0.00044068 0.000246741"/>
              <joint name="l_ankle_pitch" pos="0 0 0" axis="0 1 0" range="-0.785398 0.785398" damping="2"/>
              <geom pos="-0.02115 -0.0926 0.8506" quat="0.707107 0 0 0.707107" type="mesh" rgba="0.7 0.7 0.7 1" mesh="sim_ecub_l_ankle_1_prt"/>
              <body name="l_ankle_2" pos="-0.05275 -0.0182 -0.035">
                <inertial pos="0.0484773 -7.60796e-05 -0.0336846" quat="0.454173 0.540243 0.555237 0.439974" mass="1.98403" diaginertia="0.0126363 0.0123084 0.0028041"/>
                <joint name="l_ankle_roll" pos="0 0 0" axis="1 0 0" range="-0.436332 0.436332" damping="2"/>
                <geom pos="0.0316 -0.0744 0.8856" quat="0.707107 0 0 0.707107" type="mesh" rgba="0.3 0.3 0.3 1" mesh="sim_ecub_l_ankle_2_prt"/>
                <geom pos="0.0316 -0.0744 0.8856" quat="0.707107 0 0 0.707107" type="mesh" rgba="1 0.51 0 1" mesh="sim_ecub_l_foot_front_prt"/>
                <geom pos="0.0316 -0.0744 0.8856" quat="0.707107 0 0 0.707107" type="mesh" rgba="1 0.51 0 1" mesh="sim_ecub_l_foot_rear_prt"/>
              </body>
            </body>
          </body>
        </body>
      </body>
    </body>
    <body name="torso_1" pos="0 0 0.0605">
      <inertial pos="-0.00963997 0.00061685 0.0824423" quat="0.700604 0.0855404 0.0875458 0.702974" mass="2.06457" diaginertia="0.00740614 0.00613235 0.00299268"/>
      <joint name="torso_roll" pos="0 0 0" axis="-1 0 0" range="-0.401426 0.401426" damping="2"/>
      <geom pos="0 0 0.118" quat="0.707107 0 0 0.707107" type="mesh" rgba="0.7 0.7 0.7 1" mesh="sim_ecub_torso_1_prt"/>
      <body name="torso_2" pos="0 0 0.118">
        <inertial pos="0.00157247 0.00362235 0.0260195" quat="-0.0181108 0.0146525 0.755585 0.654636" mass="0.705163" diaginertia="0.00125929 0.00115568 0.000657438"/>
        <joint name="torso_pitch" pos="0 0 0" axis="0 1 0" range="-0.314159 0.785398" damping="2"/>
        <geom quat="0.707107 0 0 0.707107" type="mesh" rgba="0.7 0.7 0.7 1" mesh="sim_ecub_torso_2_prt"/>
        <body name="chest" pos="0 0 0.06447">
          <inertial pos="-0.010721 -0.000348206 0.076111" quat="-0.0252821 0.00885239 0.00421446 0.999632" mass="8.06547" diaginertia="0.0484694 0.044931 0.0306811"/>
          <joint name="torso_yaw" pos="0 0 0" axis="0 0 -1" range="-0.750492 0.750492" damping="2"/>
          <geom pos="0 0 -0.06447" quat="0.707107 0 0 0.707107" type="mesh" rgba="0.3 0.3 0.3 1" mesh="sim_ecub_chest_prt"/>
          <body name="neck_2" pos="0.00486151 0 0.2253">
            <inertial pos="-0.00630577 3.01413e-05 0.006373" quat="3.55339e-05 -0.281959 -0.00735769 0.959398" mass="0.121003" diaginertia="5.09387e-05 3.84906e-05 3.19869e-05"/>
            <joint name="neck_pitch" pos="0 0 0" axis="0 -1 0" range="-0.523599 0.383972" damping="2"/>
            <geom pos="-0.00486151 -5e-05 -0.28977" quat="0.707107 0 0 0.707107" type="mesh" rgba="0.7 0.7 0.7 1" mesh="sim_ecub_head_neck_2_prt"/>
            <body name="neck_3" pos="0 0 0.0095">
              <inertial pos="0.00075905 -4.09169e-05 0.036035" quat="0.711625 -0.0362238 -0.034139 0.700794" mass="0.178114" diaginertia="0.000107601 9.76645e-05 3.56511e-05"/>
              <joint name="neck_roll" pos="0 0 0" axis="1 0 0" range="-0.349066 0.349066" damping="2"/>
              <geom pos="-0.00486151 0 -0.29927" quat="0.707107 0 0 0.707107" type="mesh" rgba="0.7 0.7 0.7 1" mesh="sim_ecub_head_neck_3_prt"/>
              <body name="head" pos="0 0 0.06915">
                <inertial pos="-0.0203885 0.0040021 0.034332" quat="0.727423 0.230215 0.158946 0.626573" mass="2.31933" diaginertia="0.0122781 0.0106049 0.0100972"/>
                <joint name="neck_yaw" pos="0 0 0" axis="0 0 1" range="-0.785398 0.785398" damping="2"/>
                <geom pos="-0.00486151 0 -0.36842" quat="0.707107 0 0 0.707107" type="mesh" rgba="0.7 0.7 0.7 1" mesh="sim_ecub_head_prt"/>
                <body name="realsense" pos="0.06251 -3e-05 0.076393" quat="1 0 0.000129791 0">
                  <inertial pos="-0.0156655 0.00452 0.00274493" quat="0.194827 0.733384 -0.166258 0.62972" mass="0.0973042" diaginertia="0.000300231 0.000214678 0.000102145"/>
                  <joint name="camera_tilt" pos="0 0 0" axis="0 -1 0" range="-0.523599 0.523599" damping="2"/>
                  <geom pos="-0.067256 3e-05 -0.44483" quat="0.707107 -9.17761e-05 -9.17761e-05 0.707107" type="mesh" rgba="0 1 0 1" mesh="sim_ecub_realsense_prt"/>
                </body>
              </body>
            </body>
          </body>
          <body name="r_shoulder_1" pos="-0.0135187 -0.0670476 0.12352" quat="0.982708 -0.121688 -0.0429061 0.132799">
            <inertial pos="0.000172398 -0.0678405 0.000475572" quat="0.0238343 -0.0206203 0.702642 0.710846" mass="0.792282" diaginertia="0.00120974 0.0011959 0.000330536"/>
            <joint name="r_shoulder_pitch" pos="0 0 0" axis="-3.35225e-07 1 -2.20686e-07" range="-2.96706 0.610865" damping="2"/>
            <geom pos="0.0214149 0.106413 -0.168036" quat="0.788783 0.116385 -0.055707 0.600977" type="mesh" rgba="0.7 0.7 0.7 1" mesh="sim_ecub_r_shoulder_1_prt"/>
            <body name="r_shoulder_2" pos="0.00749996 -0.0933001 -6.00683e-07">
              <inertial pos="0.000512067 -0.000143644 -0.0364077" quat="0.681235 0.173027 0.171393 0.690366" mass="0.710693" diaginertia="0.000821732 0.000757933 0.000320608"/>
              <joint name="r_shoulder_roll" pos="0 0 0" axis="-1 1.71286e-07 2.92871e-07" range="-0.261799 2.61799" damping="2"/>
              <geom pos="0.0139014 0.199666 -0.168047" quat="0.788783 0.116385 -0.055707 0.600977" type="mesh" rgba="0.7 0.7 0.7 1" mesh="sim_ecub_r_shoulder_2_prt"/>
              <geom pos="0.0139014 0.199666 -0.168047" quat="0.788783 0.116385 -0.055707 0.600977" type="mesh" rgba="0.7 0.7 0.7 1" mesh="sim_ecub_r_shoulder_3_prt"/>
              <body name="r_upperarm" pos="-0.00684991 3.26793e-07 -0.0767999">
                <inertial pos="0.000147064 -0.00233532 -0.0501167" quat="0.797511 -0.0270149 0.0111229 0.602596" mass="1.77224" diaginertia="0.00352538 0.00341395 0.00156994"/>
                <joint name="r_shoulder_yaw" pos="0 0 0" axis="1.71338e-07 -2.36593e-07 1" range="-0.872665 1.39626" damping="2"/>
                <geom pos="0.0207514 0.199666 -0.0912466" quat="0.788783 0.116385 -0.055707 0.600977" type="mesh" rgba="0 0 0 1" mesh="sim_ecub_r_upperarm_prt"/>
                <body name="r_forearm" pos="0.01 0.00150007 -0.1237">
                  <inertial pos="-0.0183071 -0.0022154 -0.0881495" quat="0.699578 0.0118951 0.0052462 0.714438" mass="1.47607" diaginertia="0.00409465 0.00401959 0.00151591"/>
                  <joint name="r_elbow" pos="0 0 0" axis="3.35225e-07 -1 2.20686e-07" range="-0.0523599 1.309" damping="2"/>
                  <geom pos="0.0107513 0.198166 0.032453" quat="0.788783 0.116385 -0.055707 0.600977" type="mesh" rgba="0.3 0.3 0.3 1" mesh="sim_ecub_r_forearm_prt"/>
                  <body name="r_wrist_1" pos="-0.0150002 -0.00200069 -0.19435">
                    <inertial pos="0.000402763 -0.00105883 0.0191411" quat="-0.406439 0.589691 -0.2761 0.640969" mass="0.0565425" diaginertia="2.6463e-05 2.32138e-05 2.14873e-05"/>
                    <joint name="r_wrist_yaw" pos="0 0 0" axis="1.71338e-07 -2.36593e-07 1" range="-1.6057 1.6057" damping="2"/>
                    <geom pos="0.0257515 0.200167 0.226803" quat="0.788783 0.116385 -0.055707 0.600977" type="mesh" rgba="0.7 0.7 0.7 1" mesh="sim_ecub_r_wrist_1_prt"/>
                    <body name="r_wrist_2">
                      <inertial pos="0.00392272 -0.0045195 0.0122774" quat="0.641999 -0.0546285 -0.0111891 0.764675" mass="0.0264562" diaginertia="7.01483e-05 6.75861e-05 6.23239e-06"/>
                      <joint name="r_wrist_roll" pos="0 0 0" axis="1 -1.71286e-07 -2.92871e-07" range="-1.0821 0.907571" damping="2"/>
                      <geom pos="0.0257515 0.200167 0.226803" quat="0.788783 0.116385 -0.055707 0.600977" type="mesh" rgba="1 0 0 1" mesh="sim_ecub_r_wrist_2_prt"/>
                      <body name="r_hand_palm">
                        <inertial pos="-0.00386798 -0.0027925 -0.0597035" quat="0.712136 0.139615 0.0913837 0.681923" mass="0.189135" diaginertia="0.000205772 0.000141282 0.00010215"/>
                        <joint name="r_wrist_pitch" pos="0 0 0" axis="3.35225e-07 -1 2.20686e-07" range="-0.558505 0.558505" damping="2"/>
                        <geom pos="0.0257515 0.200167 0.226803" quat="0.788783 0.116385 -0.055707 0.600977" type="mesh" rgba="0 0 1 1" mesh="sim_ecub_r_hand_palm_prt"/>
                        <body name="r_hand_pinkie_1" pos="-0.0359823 0.00238868 -0.0920853" quat="0.013077 0.043616 -0.000570957 0.998963">
                          <inertial pos="0.000120667 0.00370525 -0.0119666" quat="0.653769 -0.0179979 -0.0113327 -0.756396" mass="0.00283627" diaginertia="3.10621e-07 3.00924e-07 1.49717e-07"/>
                          <joint name="r_pinkie_prox" pos="0 0 0" axis="-1 1.97921e-07 4.06013e-07" range="0 1.5708" damping="2"/>
                          <geom pos="-0.0285272 -0.199326 0.322602" quat="0.615776 -0.0881877 -0.0903306 -0.777742" type="mesh" rgba="1 1 0 1" mesh="sim_ecub_r_hand_pinkie_1_prt"/>
                          <body name="r_hand_pinkie_2" pos="0 -0.00149975 -0.0250002">
                            <inertial pos="1.71971e-05 0.00178469 -0.00561191" quat="0.999516 0.0300049 0.000303267 -0.00818798" mass="0.00857923" diaginertia="2.79657e-06 2.79081e-06 2.78798e-07"/>
                            <joint name="r_pinkie_dist" pos="0 0 0" axis="-1 1.97921e-07 4.06013e-07" range="0 1.62839" damping="2"/>
                            <geom pos="-0.0285273 -0.197827 0.347603" quat="0.615776 -0.0881877 -0.0903306 -0.777742" type="mesh" rgba="1 0 1 1" mesh="sim_ecub_r_hand_pinkie_2_prt"/>
                          </body>
                        </body>
                        <body name="r_hand_thumb_1" pos="0.0233749 0.00300008 -0.0345235" quat="0.974289 -0.022194 -0.111006 0.194796">
                          <inertial pos="0.0207581 -0.0027448 -0.00880548" quat="0.315229 0.689274 0.58566 0.287287" mass="0.0346205" diaginertia="1.04833e-05 9.20637e-06 2.92427e-06"/>
                          <joint name="r_thumb_add" pos="0 0 0" axis="9.57907e-08 6.90101e-08 1" range="0 1.5708" damping="2"/>
                          <geom pos="0.132215 0.158516 0.254094" quat="0.889171 0.18676 -0.00272445 0.417718" type="mesh" rgba="0 1 1 1" mesh="sim_ecub_r_hand_thumb_1_prt"/>
                          <body name="r_hand_thumb_2" pos="0.0345419 -0.0031448 -0.0260718" quat="0.591557 0.740051 0.199788 -0.24994">
                            <inertial pos="0.00979188 0.00433944 0.000262676" quat="0.474133 0.56279 0.455929 0.500593" mass="0.00246082" diaginertia="2.04937e-07 1.883e-07 1.37598e-07"/>
                            <joint name="r_thumb_prox" pos="0 0 0" axis="2.0368e-07 1.50085e-07 -1" range="0 1.43292" damping="2"/>
                            <geom pos="-0.0921942 0.239476 -0.219815" quat="0.559259 -0.630327 0.176553 0.508672" type="mesh" rgba="0 1 0 1" mesh="sim_ecub_r_hand_thumb_2_prt"/>
                            <body name="r_hand_thumb_3" pos="0.0199995 -0.00149952 -3.90935e-07">
                              <inertial pos="0.00646418 0.0018849 1.54041e-05" quat="0.52108 0.454001 0.542278 0.4778" mass="0.00811336" diaginertia="2.1912e-06 2.18834e-06 2.69154e-07"/>
                              <joint name="r_thumb_dist" pos="0 0 0" axis="2.0368e-07 1.50085e-07 -1" range="0 0.935496" damping="2"/>
                              <geom pos="-0.112194 0.240976 -0.219814" quat="0.559259 -0.630327 0.176553 0.508672" type="mesh" rgba="1 1 1 1" mesh="sim_ecub_r_hand_thumb_3_prt"/>
                            </body>
                          </body>
                        </body>
                        <body name="r_hand_middle_1" pos="0.00960016 0.00150086 -0.103" quat="9.28173e-08 -2.82515e-07 0 -1">
                          <inertial pos="0.000142889 0.00364327 -0.0143316" quat="0.64749 -0.0180046 -0.00717176 -0.761827" mass="0.00345703" diaginertia="4.54177e-07 4.47134e-07 1.80586e-07"/>
                          <joint name="r_middle_prox" pos="0 0 0" axis="-1 3.5692e-07 2.72158e-07" range="0 1.5708" damping="2"/>
                          <geom pos="-0.0161512 -0.198666 0.329803" quat="0.600977 -0.0557072 -0.116385 -0.788783" type="mesh" rgba="0 0 0.8 1" mesh="sim_ecub_r_hand_middle_1_prt"/>
                          <body name="r_hand_middle_2" pos="1.35502e-07 -0.00149952 -0.0300002" quat="1 -0.000936086 1.206e-10 -1.28834e-07">
                            <inertial pos="5.14311e-05 0.00159948 -0.0035911" quat="0.999401 0.0343196 0.000351618 0.00446538" mass="0.00912524" diaginertia="3.47314e-06 3.4662e-06 2.81974e-07"/>
                            <joint name="r_middle_dist" pos="0 0 0" axis="-1 9.87832e-08 2.50448e-07" range="0 1.73137" damping="2"/>
                            <geom pos="-0.0161513 -0.19784 0.359433" quat="0.601029 -0.0551446 -0.115647 -0.788891" type="mesh" rgba="0.1 0.8 0.1 1" mesh="sim_ecub_r_hand_middle_2_prt"/>
                          </body>
                        </body>
                        <body name="r_hand_ring_1" pos="-0.0154179 0.0018501 -0.0979004" quat="0.013077 0.043616 -0.000570957 0.998963">
                          <inertial pos="0.000142554 0.00364206 -0.0143318" quat="0.647388 -0.0178261 -0.00704744 -0.76192" mass="0.00345703" diaginertia="4.54402e-07 4.47358e-07 1.80643e-07"/>
                          <joint name="r_ring_prox" pos="0 0 0" axis="-1 1.97921e-07 4.06013e-07" range="0 1.5708" damping="2"/>
                          <geom pos="-0.00752724 -0.199326 0.326602" quat="0.615776 -0.0881877 -0.0903306 -0.777742" type="mesh" mesh="sim_ecub_r_hand_ring_1_prt"/>
                          <body name="r_hand_ring_2" pos="0 -0.00149992 -0.0300006">
                            <inertial pos="5.12902e-05 0.00166963 -0.00359381" quat="0.999412 0.0342734 0.000481784 0.000342581" mass="0.0091955" diaginertia="3.48042e-06 3.46644e-06 2.88518e-07"/>
                            <joint name="r_ring_dist" pos="0 0 0" axis="-1 1.97921e-07 4.06013e-07" range="0 1.73137" damping="2"/>
                            <geom pos="-0.00752719 -0.197826 0.356603" quat="0.615776 -0.0881877 -0.0903306 -0.777742" type="mesh" rgba="0 1 0 1" mesh="sim_ecub_r_hand_ring_2_prt"/>
                          </body>
                        </body>
                        <body name="r_hand_index_1" pos="0.0224701 0.00150063 -0.0685895" quat="2.31007e-08 -0.0436192 1.00859e-09 0.999048">
                          <inertial pos="-0.00875698 0.0041775 -0.0177834" quat="0.393214 -0.117543 0.0120729 -0.911823" mass="0.0183891" diaginertia="2.48938e-06 2.32534e-06 9.88262e-07"/>
                          <joint name="r_index_add" pos="0 0 0" axis="-3.99252e-07 1 2.1442e-07" range="0 0.261799" damping="2"/>
                          <geom pos="-0.0290139 -0.198666 0.293983" quat="0.595328 -0.021248 -0.142489 -0.790462" type="mesh" rgba="0 0 0 1" mesh="sim_ecub_r_hand_index_1_prt"/>
                          <body name="r_hand_index_2" pos="-0.00919255 -1.6308e-07 -0.0307136">
                            <inertial pos="0.000142732 0.00364318 -0.0143313" quat="0.64805 -0.0178217 -0.00704591 -0.761356" mass="0.00345703" diaginertia="4.54357e-07 4.47432e-07 1.80734e-07"/>
                            <joint name="r_index_prox" pos="0 0 0" axis="-1 -2.68729e-07 4.66836e-07" range="0 1.5708" damping="2"/>
                            <geom pos="-0.0198214 -0.198666 0.324696" quat="0.595328 -0.021248 -0.142489 -0.790462" type="mesh" rgba="1 0 0 1" mesh="sim_ecub_r_hand_index_2_prt"/>
                            <body name="r_hand_index_3" pos="0 -0.00149982 -0.0300005">
                              <inertial pos="4.52785e-05 0.00159986 -0.00359075" quat="0.999411 0.0343094 0.000461695 -0.000225793" mass="0.00912524" diaginertia="3.4732e-06 3.46633e-06 2.81852e-07"/>
                              <joint name="r_index_dist" pos="0 0 0" axis="-1 -2.68729e-07 4.66836e-07" range="0 1.73137" damping="2"/>
                              <geom pos="-0.0198214 -0.197166 0.354697" quat="0.595328 -0.021248 -0.142489 -0.790462" type="mesh" rgba="0 0 1 1" mesh="sim_ecub_r_hand_index_3_prt"/>
                            </body>
                          </body>
                        </body>
                      </body>
                    </body>
                  </body>
                </body>
              </body>
            </body>
          </body>
          <body name="l_shoulder_1" pos="-0.0135187 0.0670476 0.12352" quat="0.982708 0.121688 -0.0429058 -0.132799">
            <inertial pos="0.000148281 0.0678296 0.000503488" quat="0.0086468 -0.011851 0.711187 0.70285" mass="0.791376" diaginertia="0.00120905 0.00119544 0.000329558"/>
            <joint name="l_shoulder_pitch" pos="0 0 0" axis="1.4959e-07 1 2.72203e-07" range="-2.96706 0.610865" damping="2"/>
            <geom pos="0.0214151 -0.106413 -0.168036" quat="0.600977 -0.0557072 0.116385 0.788783" type="mesh" rgba="0.7 0.7 0.7 1" mesh="sim_ecub_l_shoulder_1_prt"/>
            <body name="l_shoulder_2" pos="0.00500013 0.0932995 -4.34136e-07">
              <inertial pos="0.00302787 0.000128307 -0.0364069" quat="0.68686 0.173186 0.172996 0.684326" mass="0.712399" diaginertia="0.000824775 0.000759006 0.000323849"/>
              <joint name="l_shoulder_roll" pos="0 0 0" axis="1 3.5692e-07 2.72158e-07" range="-0.261799 2.61799" damping="2"/>
              <geom pos="0.0164285 -0.199759 -0.168024" quat="0.600977 -0.0557072 0.116385 0.788783" type="mesh" rgba="0.7 0.7 0.7 1" mesh="sim_ecub_l_shoulder_2_prt"/>
              <geom pos="0.0164285 -0.199759 -0.168024" quat="0.600977 -0.0557072 0.116385 0.788783" type="mesh" rgba="0.7 0.7 0.7 1" mesh="sim_ecub_l_shoulder_3_prt"/>
              <body name="l_upperarm" pos="-0.00435007 2.43599e-07 -0.0768001">
                <inertial pos="0.00013045 0.00225331 -0.0500647" quat="0.610168 0.0102954 -0.0258805 0.791783" mass="1.77085" diaginertia="0.00352386 0.00341014 0.00156558"/>
                <joint name="l_shoulder_yaw" pos="0 0 0" axis="3.93691e-07 -1.85076e-07 -1" range="-0.872665 1.39626" damping="2"/>
                <geom pos="0.0207786 -0.19976 -0.0912239" quat="0.600977 -0.0557072 0.116385 0.788783" type="mesh" rgba="1 1 0 1" mesh="sim_ecub_l_upperarm_prt"/>
                <body name="l_forearm" pos="0.0100001 -0.00150006 -0.1237">
                  <inertial pos="-0.0185533 0.00231201 -0.0891937" quat="0.691135 0.00462341 0.00785964 0.722669" mass="1.46045" diaginertia="0.00396763 0.00389429 0.00150537"/>
                  <joint name="l_elbow" pos="0 0 0" axis="-1.4959e-07 -1 -2.72203e-07" range="-0.0523599 1.309" damping="2"/>
                  <geom pos="0.0107785 -0.19826 0.0324758" quat="0.600977 -0.0557072 0.116385 0.788783" type="mesh" rgba="0.3 0.3 0.3 1" mesh="sim_ecub_l_forearm_prt"/>
                  <body name="l_wrist_1" pos="-0.0150001 0.0020007 -0.19435">
                    <inertial pos="-0.000402554 0.0010582 0.0191411" quat="0.276209 0.64093 0.406449 0.589676" mass="0.0565425" diaginertia="2.64624e-05 2.32129e-05 2.14859e-05"/>
                    <joint name="l_wrist_yaw" pos="0 0 0" axis="3.93691e-07 -1.85076e-07 -1" range="-1.6057 1.6057" damping="2"/>
                    <geom pos="0.0257786 -0.20026 0.226826" quat="0.600977 -0.0557072 0.116385 0.788783" type="mesh" rgba="0.7 0.7 0.7 1" mesh="sim_ecub_l_wrist_1_prt"/>
                    <body name="l_wrist_2">
                      <inertial pos="0.000104619 0.00233529 -0.00539419" quat="-0.0125435 0.704722 -0.0178029 0.70915" mass="0.00945549" diaginertia="8.41917e-07 6.68331e-07 4.29897e-07"/>
                      <joint name="l_wrist_roll" pos="0 0 0" axis="-1 -3.5692e-07 -2.72158e-07" range="-1.0821 0.907571" damping="2"/>
                      <geom pos="0.0257786 -0.20026 0.226826" quat="0.600977 -0.0557072 0.116385 0.788783" type="mesh" rgba="1 0 1 1" mesh="sim_ecub_l_wrist_2_prt"/>
                      <body name="l_hand_palm">
                        <inertial pos="-0.00346408 0.00265951 -0.0591591" quat="0.686659 0.106269 0.147177 0.70395" mass="0.193024" diaginertia="0.000212102 0.000146186 0.000104322"/>
                        <joint name="l_wrist_pitch" pos="0 0 0" axis="-1.4959e-07 -1 -2.72203e-07" range="-0.558505 0.558505" damping="2"/>
                        <geom pos="0.0257786 -0.20026 0.226826" quat="0.600977 -0.0557072 0.116385 0.788783" type="mesh" rgba="0 1 1 1" mesh="sim_ecub_l_hand_palm_prt"/>
                        <body name="l_hand_ring_1" pos="-0.0154179 -0.0018501 -0.0979004" quat="0.998963 -0.000570958 0.0436157 0.0130771">
                          <inertial pos="0.000142803 0.00364267 -0.0143315" quat="0.762078 -0.00717286 0.0179149 0.647197" mass="0.00345703" diaginertia="4.5428e-07 4.47288e-07 1.80584e-07"/>
                          <joint name="l_ring_prox" pos="0 0 0" axis="-1 -1.97921e-07 -4.06013e-07" range="0 1.5708" damping="2"/>
                          <geom pos="0.00754985 -0.199421 0.326627" quat="0.615776 -0.0881877 0.0903306 0.777742" type="mesh" rgba="0 1 0 1" mesh="sim_ecub_l_hand_ring_1_prt"/>
                          <body name="l_hand_ring_2" pos="0 -0.00149992 -0.0300006">
                            <inertial pos="5.15864e-05 0.00159962 -0.0035906" quat="-0.00222444 0.00042108 -0.0342879 0.999409" mass="0.00912524" diaginertia="3.47293e-06 3.46579e-06 2.81896e-07"/>
                            <joint name="l_ring_dist" pos="0 0 0" axis="-1 -1.97921e-07 -4.06013e-07" range="0 1.73137" damping="2"/>
                            <geom pos="0.0075498 -0.197921 0.356628" quat="0.615776 -0.0881877 0.0903306 0.777742" type="mesh" rgba="1 1 1 1" mesh="sim_ecub_l_hand_ring_2_prt"/>
                          </body>
                        </body>
                        <body name="l_hand_index_1" pos="0.02247 -0.00155003 -0.0685901" quat="0.999048 4.95894e-09 -0.0436194 1.13578e-07">
                          <inertial pos="0.00877527 0.00426945 -0.0177506" quat="0.371801 -0.118732 -0.0120257 0.92061" mass="0.0183891" diaginertia="2.48601e-06 2.32767e-06 1.00012e-06"/>
                          <joint name="l_index_add" pos="0 0 0" axis="-3.99252e-07 -1 -2.1442e-07" range="0 0.261799" damping="2"/>
                          <geom pos="0.0290432 -0.19871 0.294003" quat="0.595328 -0.021248 0.142489 0.790462" type="mesh" rgba="0 0 0.8 1" mesh="sim_ecub_l_hand_index_1_prt"/>
                          <body name="l_hand_index_2" pos="0.00919255 -1.6308e-07 -0.0307136">
                            <inertial pos="0.000142991 0.00364213 -0.0143309" quat="0.762313 -0.00694808 0.017814 0.646925" mass="0.00345703" diaginertia="4.54395e-07 4.47421e-07 1.80696e-07"/>
                            <joint name="l_index_prox" pos="0 0 0" axis="-1 2.68729e-07 -4.66836e-07" range="0 1.5708" damping="2"/>
                            <geom pos="0.0198506 -0.19871 0.324717" quat="0.595328 -0.021248 0.142489 0.790462" type="mesh" rgba="0.1 0.8 0.1 1" mesh="sim_ecub_l_hand_index_2_prt"/>
                            <body name="l_hand_index_3" pos="0 -0.00150063 -0.0299992">
                              <inertial pos="5.91094e-05 0.00160012 -0.00359103" quat="-0.0131768 0.000106624 -0.0342879 0.999325" mass="0.00912524" diaginertia="3.47312e-06 3.46608e-06 2.81804e-07"/>
                              <joint name="l_index_dist" pos="0 0 0" axis="-1 2.68729e-07 -4.66836e-07" range="0 1.73137" damping="2"/>
                              <geom pos="0.0198507 -0.197209 0.354716" quat="0.595328 -0.021248 0.142489 0.790462" type="mesh" mesh="sim_ecub_l_hand_index_3_prt"/>
                            </body>
                          </body>
                        </body>
                        <body name="l_hand_middle_1" pos="0.00960021 -0.00150086 -0.103">
                          <inertial pos="0.000142679 0.00364282 -0.0143314" quat="0.761722 -0.00711679 0.017894 0.647618" mass="0.00345703" diaginertia="4.54378e-07 4.4737e-07 1.80642e-07"/>
                          <joint name="l_middle_prox" pos="0 0 0" axis="-1 -3.5692e-07 -2.72158e-07" range="0 1.5708" damping="2"/>
                          <geom pos="0.0161784 -0.198759 0.329826" quat="0.600977 -0.0557072 0.116385 0.788783" type="mesh" rgba="0 1 0 1" mesh="sim_ecub_l_hand_middle_1_prt"/>
                          <body name="l_hand_middle_2" pos="-1.35502e-07 -0.00149952 -0.0300002" quat="1 -0.000936086 -1.206e-10 1.28834e-07">
                            <inertial pos="5.17212e-05 0.00159963 -0.00359048" quat="0.00309236 0.000599847 -0.0343229 0.999406" mass="0.00912524" diaginertia="3.47349e-06 3.46643e-06 2.82025e-07"/>
                            <joint name="l_middle_dist" pos="0 0 0" axis="-1 -9.87832e-08 -2.50448e-07" range="0 1.73137" damping="2"/>
                            <geom pos="0.0161784 -0.197933 0.359456" quat="0.601029 -0.0551446 0.115647 0.788891" type="mesh" rgba="0 0 0 1" mesh="sim_ecub_l_hand_middle_2_prt"/>
                          </body>
                        </body>
                        <body name="l_hand_thumb_1" pos="0.0233749 -0.00300007 -0.0345235" quat="0.974289 0.0221941 -0.111006 -0.194796">
                          <inertial pos="0.020688 0.00325522 -0.00889694" quat="0.276441 0.577253 0.697628 0.321985" mass="0.0346205" diaginertia="1.05426e-05 9.25603e-06 2.90959e-06"/>
                          <joint name="l_thumb_add" pos="0 0 0" axis="-9.57907e-08 6.90101e-08 -1" range="0 1.5708" damping="2"/>
                          <geom pos="0.13228 -0.15859 0.25411" quat="0.417718 -0.00272445 0.18676 0.889171" type="mesh" rgba="1 0 0 1" mesh="sim_ecub_l_hand_thumb_1_prt"/>
                          <body name="l_hand_thumb_2" pos="0.0345419 0.0031448 -0.0260718" quat="0.740051 0.591557 0.24994 -0.199788">
                            <inertial pos="0.00979199 0.0043397 0.000262957" quat="-0.474217 -0.562755 -0.456673 -0.499876" mass="0.00246082" diaginertia="2.04895e-07 1.88296e-07 1.37557e-07"/>
                            <joint name="l_thumb_prox" pos="0 0 0" axis="6.65069e-07 -2.78248e-07 -1" range="0 1.43292" damping="2"/>
                            <geom pos="-0.0921523 0.239511 0.219898" quat="-0.176554 0.508672 -0.559259 -0.630327" type="mesh" rgba="0 0 1 1" mesh="sim_ecub_l_hand_thumb_2_prt"/>
                            <body name="l_hand_thumb_3" pos="0.0199995 -0.00149952 4.08502e-07">
                              <inertial pos="0.00646466 0.00188449 1.55303e-05" quat="-0.520446 -0.454685 -0.541701 -0.478495" mass="0.00811336" diaginertia="2.19131e-06 2.18829e-06 2.69415e-07"/>
                              <joint name="l_thumb_dist" pos="0 0 0" axis="6.65069e-07 -2.78248e-07 -1" range="0 0.935496" damping="2"/>
                              <geom pos="-0.112152 0.241011 0.219898" quat="-0.176554 0.508672 -0.559259 -0.630327" type="mesh" rgba="1 1 0 1" mesh="sim_ecub_l_hand_thumb_3_prt"/>
                            </body>
                          </body>
                        </body>
                        <body name="l_hand_pinkie_1" pos="-0.0359822 -0.00238868 -0.0920854" quat="0.998963 -0.000570958 0.0436157 0.0130771">
                          <inertial pos="0.000120758 0.0037049 -0.0119662" quat="0.756804 -0.0113226 0.0180073 0.653295" mass="0.00283627" diaginertia="3.10578e-07 3.00785e-07 1.49698e-07"/>
                          <joint name="l_pinkie_prox" pos="0 0 0" axis="-1 -1.97921e-07 -4.06013e-07" range="0 1.5708" damping="2"/>
                          <geom pos="0.0285498 -0.19942 0.322627" quat="0.615776 -0.0881877 0.0903306 0.777742" type="mesh" rgba="1 0 1 1" mesh="sim_ecub_l_hand_pinkie_1_prt"/>
                          <body name="l_hand_pinkie_2" pos="0 -0.00149975 -0.0250002" quat="1 1.78156e-05 -2.97285e-07 -2.62248e-07">
                            <inertial pos="1.71256e-05 0.00178522 -0.00561227" quat="0.0112566 0.000404689 -0.0300218 0.999486" mass="0.00857923" diaginertia="2.79619e-06 2.79081e-06 2.78845e-07"/>
                            <joint name="l_pinkie_dist" pos="0 0 0" axis="-1 -7.2242e-07 1.88573e-07" range="0 1.62839" damping="2"/>
                            <geom pos="0.0285502 -0.197908 0.347634" quat="0.615774 -0.0881984 0.0903446 0.777741" type="mesh" rgba="0 1 1 1" mesh="sim_ecub_l_hand_pinkie_2_prt"/>
                          </body>
                        </body>
                      </body>
                    </body>
                  </body>
                </body>
              </body>
            </body>
          </body>
        </body>
      </body>
    </body>
  </worldbody>
</mujoco>
